RMSE: 1.4889
MAE:  1.2690
Traceback (most recent call last):
  File "/home/anatolii-shara/Documents/mlops_projector/venv/lib/python3.12/site-packages/pandas/core/indexes/base.py", line 3805, in get_loc
    return self._engine.get_loc(casted_key)
           ^^^^^^^^^^^^^^^^^^^^^^^^^^^^^^^^
  File "index.pyx", line 167, in pandas._libs.index.IndexEngine.get_loc
  File "index.pyx", line 196, in pandas._libs.index.IndexEngine.get_loc
  File "pandas/_libs/hashtable_class_helper.pxi", line 7081, in pandas._libs.hashtable.PyObjectHashTable.get_item
  File "pandas/_libs/hashtable_class_helper.pxi", line 7089, in pandas._libs.hashtable.PyObjectHashTable.get_item
KeyError: 'description'

The above exception was the direct cause of the following exception:

Traceback (most recent call last):
  File "/home/anatolii-shara/Documents/mlops_projector/hw5/train_and_recommend.py", line 60, in <module>
    tfidf_matrix = vectorizer.fit_transform(books_df["description"])
                                            ~~~~~~~~^^^^^^^^^^^^^^^
  File "/home/anatolii-shara/Documents/mlops_projector/venv/lib/python3.12/site-packages/pandas/core/frame.py", line 4102, in __getitem__
    indexer = self.columns.get_loc(key)
              ^^^^^^^^^^^^^^^^^^^^^^^^^
  File "/home/anatolii-shara/Documents/mlops_projector/venv/lib/python3.12/site-packages/pandas/core/indexes/base.py", line 3812, in get_loc
    raise KeyError(key) from err
KeyError: 'description'
