README.md: 100%|███████████████████████████████████████████████████████████████████████████████████████████████████████████████████████████████████| 3.89k/3.89k [00:00<00:00, 9.08MB/s]
Traceback (most recent call last):
  File "/home/anatolii-shara/Documents/mlops_projector/venv/lib/python3.12/site-packages/huggingface_hub/utils/_http.py", line 409, in hf_raise_for_status
    response.raise_for_status()
  File "/home/anatolii-shara/Documents/mlops_projector/venv/lib/python3.12/site-packages/requests/models.py", line 1024, in raise_for_status
    raise HTTPError(http_error_msg, response=self)
requests.exceptions.HTTPError: 404 Client Error: Not Found for url: https://huggingface.co/paraphrase-multilingual-MiniLM-L12-v2/resolve/main/tokenizer_config.json

The above exception was the direct cause of the following exception:

Traceback (most recent call last):
  File "/home/anatolii-shara/Documents/mlops_projector/venv/lib/python3.12/site-packages/transformers/utils/hub.py", line 424, in cached_files
    hf_hub_download(
  File "/home/anatolii-shara/Documents/mlops_projector/venv/lib/python3.12/site-packages/huggingface_hub/utils/_validators.py", line 114, in _inner_fn
    return fn(*args, **kwargs)
           ^^^^^^^^^^^^^^^^^^^
  File "/home/anatolii-shara/Documents/mlops_projector/venv/lib/python3.12/site-packages/huggingface_hub/file_download.py", line 961, in hf_hub_download
    return _hf_hub_download_to_cache_dir(
           ^^^^^^^^^^^^^^^^^^^^^^^^^^^^^^
  File "/home/anatolii-shara/Documents/mlops_projector/venv/lib/python3.12/site-packages/huggingface_hub/file_download.py", line 1068, in _hf_hub_download_to_cache_dir
    _raise_on_head_call_error(head_call_error, force_download, local_files_only)
  File "/home/anatolii-shara/Documents/mlops_projector/venv/lib/python3.12/site-packages/huggingface_hub/file_download.py", line 1596, in _raise_on_head_call_error
    raise head_call_error
  File "/home/anatolii-shara/Documents/mlops_projector/venv/lib/python3.12/site-packages/huggingface_hub/file_download.py", line 1484, in _get_metadata_or_catch_error
    metadata = get_hf_file_metadata(
               ^^^^^^^^^^^^^^^^^^^^^
  File "/home/anatolii-shara/Documents/mlops_projector/venv/lib/python3.12/site-packages/huggingface_hub/utils/_validators.py", line 114, in _inner_fn
    return fn(*args, **kwargs)
           ^^^^^^^^^^^^^^^^^^^
  File "/home/anatolii-shara/Documents/mlops_projector/venv/lib/python3.12/site-packages/huggingface_hub/file_download.py", line 1401, in get_hf_file_metadata
    r = _request_wrapper(
        ^^^^^^^^^^^^^^^^^
  File "/home/anatolii-shara/Documents/mlops_projector/venv/lib/python3.12/site-packages/huggingface_hub/file_download.py", line 285, in _request_wrapper
    response = _request_wrapper(
               ^^^^^^^^^^^^^^^^^
  File "/home/anatolii-shara/Documents/mlops_projector/venv/lib/python3.12/site-packages/huggingface_hub/file_download.py", line 309, in _request_wrapper
    hf_raise_for_status(response)
  File "/home/anatolii-shara/Documents/mlops_projector/venv/lib/python3.12/site-packages/huggingface_hub/utils/_http.py", line 459, in hf_raise_for_status
    raise _format(RepositoryNotFoundError, message, response) from e
huggingface_hub.errors.RepositoryNotFoundError: 404 Client Error. (Request ID: Root=1-680cbf71-4e8236902bf7cb1f5f724797;28a6960d-b4b5-4921-90ad-3914f8f5b93c)

Repository Not Found for url: https://huggingface.co/paraphrase-multilingual-MiniLM-L12-v2/resolve/main/tokenizer_config.json.
Please make sure you specified the correct `repo_id` and `repo_type`.
If you are trying to access a private or gated repo, make sure you are authenticated. For more details, see https://huggingface.co/docs/huggingface_hub/authentication

The above exception was the direct cause of the following exception:

Traceback (most recent call last):
  File "/home/anatolii-shara/Documents/mlops_projector/hw5/train_recommend_llm.py", line 68, in <module>
    tokenizer = AutoTokenizer.from_pretrained(model_name)
                ^^^^^^^^^^^^^^^^^^^^^^^^^^^^^^^^^^^^^^^^^
  File "/home/anatolii-shara/Documents/mlops_projector/venv/lib/python3.12/site-packages/transformers/models/auto/tokenization_auto.py", line 946, in from_pretrained
    tokenizer_config = get_tokenizer_config(pretrained_model_name_or_path, **kwargs)
                       ^^^^^^^^^^^^^^^^^^^^^^^^^^^^^^^^^^^^^^^^^^^^^^^^^^^^^^^^^^^^^
  File "/home/anatolii-shara/Documents/mlops_projector/venv/lib/python3.12/site-packages/transformers/models/auto/tokenization_auto.py", line 778, in get_tokenizer_config
    resolved_config_file = cached_file(
                           ^^^^^^^^^^^^
  File "/home/anatolii-shara/Documents/mlops_projector/venv/lib/python3.12/site-packages/transformers/utils/hub.py", line 266, in cached_file
    file = cached_files(path_or_repo_id=path_or_repo_id, filenames=[filename], **kwargs)
           ^^^^^^^^^^^^^^^^^^^^^^^^^^^^^^^^^^^^^^^^^^^^^^^^^^^^^^^^^^^^^^^^^^^^^^^^^^^^^
  File "/home/anatolii-shara/Documents/mlops_projector/venv/lib/python3.12/site-packages/transformers/utils/hub.py", line 456, in cached_files
    raise OSError(
OSError: paraphrase-multilingual-MiniLM-L12-v2 is not a local folder and is not a valid model identifier listed on 'https://huggingface.co/models'
If this is a private repository, make sure to pass a token having permission to this repo either by logging in with `huggingface-cli login` or by passing `token=<your_token>`
Traceback (most recent call last):
  File "/home/anatolii-shara/Documents/mlops_projector/venv/lib/python3.12/site-packages/huggingface_hub/utils/_http.py", line 409, in hf_raise_for_status
    response.raise_for_status()
  File "/home/anatolii-shara/Documents/mlops_projector/venv/lib/python3.12/site-packages/requests/models.py", line 1024, in raise_for_status
    raise HTTPError(http_error_msg, response=self)
requests.exceptions.HTTPError: 404 Client Error: Not Found for url: https://huggingface.co/paraphrase-multilingual-MiniLM-L12-v2/resolve/main/tokenizer_config.json

The above exception was the direct cause of the following exception:

Traceback (most recent call last):
  File "/home/anatolii-shara/Documents/mlops_projector/venv/lib/python3.12/site-packages/transformers/utils/hub.py", line 424, in cached_files
    hf_hub_download(
  File "/home/anatolii-shara/Documents/mlops_projector/venv/lib/python3.12/site-packages/huggingface_hub/utils/_validators.py", line 114, in _inner_fn
    return fn(*args, **kwargs)
           ^^^^^^^^^^^^^^^^^^^
  File "/home/anatolii-shara/Documents/mlops_projector/venv/lib/python3.12/site-packages/huggingface_hub/file_download.py", line 961, in hf_hub_download
    return _hf_hub_download_to_cache_dir(
           ^^^^^^^^^^^^^^^^^^^^^^^^^^^^^^
  File "/home/anatolii-shara/Documents/mlops_projector/venv/lib/python3.12/site-packages/huggingface_hub/file_download.py", line 1068, in _hf_hub_download_to_cache_dir
    _raise_on_head_call_error(head_call_error, force_download, local_files_only)
  File "/home/anatolii-shara/Documents/mlops_projector/venv/lib/python3.12/site-packages/huggingface_hub/file_download.py", line 1596, in _raise_on_head_call_error
    raise head_call_error
  File "/home/anatolii-shara/Documents/mlops_projector/venv/lib/python3.12/site-packages/huggingface_hub/file_download.py", line 1484, in _get_metadata_or_catch_error
    metadata = get_hf_file_metadata(
               ^^^^^^^^^^^^^^^^^^^^^
  File "/home/anatolii-shara/Documents/mlops_projector/venv/lib/python3.12/site-packages/huggingface_hub/utils/_validators.py", line 114, in _inner_fn
    return fn(*args, **kwargs)
           ^^^^^^^^^^^^^^^^^^^
  File "/home/anatolii-shara/Documents/mlops_projector/venv/lib/python3.12/site-packages/huggingface_hub/file_download.py", line 1401, in get_hf_file_metadata
    r = _request_wrapper(
        ^^^^^^^^^^^^^^^^^
  File "/home/anatolii-shara/Documents/mlops_projector/venv/lib/python3.12/site-packages/huggingface_hub/file_download.py", line 285, in _request_wrapper
    response = _request_wrapper(
               ^^^^^^^^^^^^^^^^^
  File "/home/anatolii-shara/Documents/mlops_projector/venv/lib/python3.12/site-packages/huggingface_hub/file_download.py", line 309, in _request_wrapper
    hf_raise_for_status(response)
  File "/home/anatolii-shara/Documents/mlops_projector/venv/lib/python3.12/site-packages/huggingface_hub/utils/_http.py", line 459, in hf_raise_for_status
    raise _format(RepositoryNotFoundError, message, response) from e
huggingface_hub.errors.RepositoryNotFoundError: 404 Client Error. (Request ID: Root=1-680cbf71-4e8236902bf7cb1f5f724797;28a6960d-b4b5-4921-90ad-3914f8f5b93c)

Repository Not Found for url: https://huggingface.co/paraphrase-multilingual-MiniLM-L12-v2/resolve/main/tokenizer_config.json.
Please make sure you specified the correct `repo_id` and `repo_type`.
If you are trying to access a private or gated repo, make sure you are authenticated. For more details, see https://huggingface.co/docs/huggingface_hub/authentication

The above exception was the direct cause of the following exception:

Traceback (most recent call last):
  File "/home/anatolii-shara/Documents/mlops_projector/hw5/train_recommend_llm.py", line 68, in <module>
    tokenizer = AutoTokenizer.from_pretrained(model_name)
                ^^^^^^^^^^^^^^^^^^^^^^^^^^^^^^^^^^^^^^^^^
  File "/home/anatolii-shara/Documents/mlops_projector/venv/lib/python3.12/site-packages/transformers/models/auto/tokenization_auto.py", line 946, in from_pretrained
    tokenizer_config = get_tokenizer_config(pretrained_model_name_or_path, **kwargs)
                       ^^^^^^^^^^^^^^^^^^^^^^^^^^^^^^^^^^^^^^^^^^^^^^^^^^^^^^^^^^^^^
  File "/home/anatolii-shara/Documents/mlops_projector/venv/lib/python3.12/site-packages/transformers/models/auto/tokenization_auto.py", line 778, in get_tokenizer_config
    resolved_config_file = cached_file(
                           ^^^^^^^^^^^^
  File "/home/anatolii-shara/Documents/mlops_projector/venv/lib/python3.12/site-packages/transformers/utils/hub.py", line 266, in cached_file
    file = cached_files(path_or_repo_id=path_or_repo_id, filenames=[filename], **kwargs)
           ^^^^^^^^^^^^^^^^^^^^^^^^^^^^^^^^^^^^^^^^^^^^^^^^^^^^^^^^^^^^^^^^^^^^^^^^^^^^^
  File "/home/anatolii-shara/Documents/mlops_projector/venv/lib/python3.12/site-packages/transformers/utils/hub.py", line 456, in cached_files
    raise OSError(
OSError: paraphrase-multilingual-MiniLM-L12-v2 is not a local folder and is not a valid model identifier listed on 'https://huggingface.co/models'
If this is a private repository, make sure to pass a token having permission to this repo either by logging in with `huggingface-cli login` or by passing `token=<your_token>`
