Traceback (most recent call last):
  File "/home/anatolii-shara/Documents/mlops_projector/hw5/train_and_recommend.py", line 62, in <module>
    books_df = pd.read_csv("data/labeled_synthetic_books_dataset_updated.csv")
               ^^^^^^^^^^^^^^^^^^^^^^^^^^^^^^^^^^^^^^^^^^^^^^^^^^^^^^^^^^^^^^^
  File "/home/anatolii-shara/Documents/mlops_projector/venv/lib/python3.12/site-packages/pandas/io/parsers/readers.py", line 1026, in read_csv
    return _read(filepath_or_buffer, kwds)
           ^^^^^^^^^^^^^^^^^^^^^^^^^^^^^^^
  File "/home/anatolii-shara/Documents/mlops_projector/venv/lib/python3.12/site-packages/pandas/io/parsers/readers.py", line 620, in _read
    parser = TextFileReader(filepath_or_buffer, **kwds)
             ^^^^^^^^^^^^^^^^^^^^^^^^^^^^^^^^^^^^^^^^^^
  File "/home/anatolii-shara/Documents/mlops_projector/venv/lib/python3.12/site-packages/pandas/io/parsers/readers.py", line 1620, in __init__
    self._engine = self._make_engine(f, self.engine)
                   ^^^^^^^^^^^^^^^^^^^^^^^^^^^^^^^^^
  File "/home/anatolii-shara/Documents/mlops_projector/venv/lib/python3.12/site-packages/pandas/io/parsers/readers.py", line 1880, in _make_engine
    self.handles = get_handle(
                   ^^^^^^^^^^^
  File "/home/anatolii-shara/Documents/mlops_projector/venv/lib/python3.12/site-packages/pandas/io/common.py", line 873, in get_handle
    handle = open(
             ^^^^^
FileNotFoundError: [Errno 2] No such file or directory: 'data/labeled_synthetic_books_dataset_updated.csv'
